Workbook
Name SegmentaçãodeDados_Anos__DATA: #N/A
Name SegmentaçãodeDados_Meses__DATA: #N/A

Sheet CONFIG
A1: SIM | E1: =TODAY() -> 46254 | G1: "Sentimos sua falta!"
A2: NÃO | B2: META
B3: 288000 | G3: Estamos há prontos para renovar nossa parceria! Volte a comprar conosco e descubra ofertas exclusivas pensadas para você.
A5: 149 CLIENTES 19/11/2024
B7: LABORATORIO
B8: VETERINARIA
B9: INDUSTRIA
B10: FARMACIA
B11: HOSPITAL
B12: FACULDADE
B13: REVENDA

Sheet DINAMICOS
B1: =GETPIVOTDATA("VALOR INSUMOS",$B$2) -> 135392.18 | D1: =GETPIVOTDATA("VALOR EQUIPAMENTO",$D$2) -> 7920 | F1: =GETPIVOTDATA("PEDIDO INSUMOS",$F$2) -> 47 | H1: =GETPIVOTDATA("PEDIDO EQUIPAMENTO",$H$2) -> 0
B2: Soma de VALOR INSUMOS | D2: Soma de VALOR EQUIPAMENTO | F2: Contagem de PEDIDO INSUMOS | H2: Contagem de PEDIDO EQUIPAMENTO
B3: 135392.18 | D3: 7920 | F3: 47

Sheet LIGACAO
A1: CLIENTE | B1: NOME | C1: RESPONSÁVEL | D1: DATA | E1: HORA | F1: ATENDEU | G1: OBSERVAÇÃO | H1: VISITA | I1: MOTIVO
A2: 704 | B2: =IFERROR(VLOOKUP(A2,CLIENTES!A:E,2,0),"CADASTRAR CLIENTE") -> LAB. ONUMA E BASILIO S/C LTDA | C2: Dra Rosely | D2: 45723 | E2: 0.4375

Sheet CLIENTES
A1: SKU | B1: NOME | C1: EMAIL | D1: WHATS | E1: CIDADE | F1: SEGMENTO | G1: PRIMEIRA COMPRA | H1: ULTIMA COMPRA | I1: INAT(DIAS) | J1: EMAIL | K1: OBSERVAÇÃO
A2: 171 | B2: HOSPITAL BENEFICENTE SAO JOSE | C2: hospitalbsaojose@hotmail.com | E2: HERCULANDIA | G2: =_xlfn.MINIFS(DADOS!$I:$I,DADOS!$B:$B,B2) -> 45377 | H2: =_xlfn.MAXIFS(DADOS!$I:$I,DADOS!$B:$B,B2) -> 46185 | I2: =CONFIG!$E$1-CLIENTES!H2 -> 69 | J2: =HYPERLINK("mailto:"&C2&"?subject="&CONFIG!$G$1&"&body="&CONFIG!$G$3,"Enviar e-mail") -> Enviar e-mail
A3: 197 | B3: LAB.ANAL.CLIN.DE ITAPETININGA | C3: acaruj@globo.com | E3: ITAPETININGA | G3: =_xlfn.MINIFS(DADOS!$I:$I,DADOS!$B:$B,B3) -> 45432 | H3: =_xlfn.MAXIFS(DADOS!$I:$I,DADOS!$B:$B,B3) -> 46217 | I3: =CONFIG!$E$1-CLIENTES!H3 -> 37 | J3: =HYPERLINK("mailto:"&C3&"?subject="&CONFIG!$G$1&"&body="&CONFIG!$G$3,"Enviar e-mail") -> Enviar e-mail
A4: 311 | B4: CENTRO DE ANAL.CLIN. UNILAB SC LTDA. | C4: marcia@laboratoriounilab.com.br | E4: PRESIDENTE PRUDENTE | G4: =_xlfn.MINIFS(DADOS!$I:$I,DADOS!$B:$B,B4) -> 45369 | H4: =_xlfn.MAXIFS(DADOS!$I:$I,DADOS!$B:$B,B4) -> 46240 | I4: =CONFIG!$E$1-CLIENTES!H4 -> 14 | J4: =HYPERLINK("mailto:"&C4&"?subject="&CONFIG!$G$1&"&body="&CONFIG!$G$3,"Enviar e-mail") -> Enviar e-mail
A5: 325 | B5: EXAME-LABORAT. DE ANAL. CLIN. CITODIAGNOSTICO S/S LTDA | C5: luizernesto@laboratorioexame.com | E5: PRESIDENTE PRUDENTE | G5: =_xlfn.MINIFS(DADOS!$I:$I,DADOS!$B:$B,B5) -> 45421 | H5: =_xlfn.MAXIFS(DADOS!$I:$I,DADOS!$B:$B,B5) -> 46247 | I5: =CONFIG!$E$1-CLIENTES!H5 -> 7 | J5: =HYPERLINK("mailto:"&C5&"?subject="&CONFIG!$G$1&"&body="&CONFIG!$G$3,"Enviar e-mail") -> Enviar e-mail
A6: 335 | B6: LABORATORIO VIDA S/S LTDA | C6: laboratorio.vida@yahoo.com.br | E6: PEDERNEIRAS | G6: =_xlfn.MINIFS(DADOS!$I:$I,DADOS!$B:$B,B6) -> 45352 | H6: =_xlfn.MAXIFS(DADOS!$I:$I,DADOS!$B:$B,B6) -> 45588 | I6: =CONFIG!$E$1-CLIENTES!H6 -> 666 | J6: =HYPERLINK("mailto:"&C6&"?subject="&CONFIG!$G$1&"&body="&CONFIG!$G$3,"Enviar e-mail") -> Enviar e-mail
A7: 364 | B7: VITALIS LAB.ANAL.CLIN.S/C LTDA | C7: vitalisitatinga@hotmail.com | E7: ITATINGA | G7: =_xlfn.MINIFS(DADOS!$I:$I,DADOS!$B:$B,B7) -> 45359 | H7: =_xlfn.MAXIFS(DADOS!$I:$I,DADOS!$B:$B,B7) -> 46093 | I7: =CONFIG!$E$1-CLIENTES!H7 -> 161 | J7: =HYPERLINK("mailto:"&C7&"?subject="&CONFIG!$G$1&"&body="&CONFIG!$G$3,"Enviar e-mail") -> Enviar e-mail
A8: 380 | B8: SANTA CASA DE CARIDADE DE GUARANESIA | C8: lucia.avelino@yahoo.com.br | E8: GUARANESIA | G8: =_xlfn.MINIFS(DADOS!$I:$I,DADOS!$B:$B,B8) -> 45594 | H8: =_xlfn.MAXIFS(DADOS!$I:$I,DADOS!$B:$B,B8) -> 45594 | I8: =CONFIG!$E$1-CLIENTES!H8 -> 660 | J8: =HYPERLINK("mailto:"&C8&"?subject="&CONFIG!$G$1&"&body="&CONFIG!$G$3,"Enviar e-mail") -> Enviar e-mail
A9: 412 | B9: LAB.ANAL.CLIN.SAO MANUEL SC LTDA. | C9: lab.sm@bol.com.br | E9: SAO MANUEL | G9: =_xlfn.MINIFS(DADOS!$I:$I,DADOS!$B:$B,B9) -> 45414 | H9: =_xlfn.MAXIFS(DADOS!$I:$I,DADOS!$B:$B,B9) -> 46216 | I9: =CONFIG!$E$1-CLIENTES!H9 -> 38 | J9: =HYPERLINK("mailto:"&C9&"?subject="&CONFIG!$G$1&"&body="&CONFIG!$G$3,"Enviar e-mail") -> Enviar e-mail
A10: 432 | B10: LABORATORIO PASTEUR HEMATOLOGIA E MICROBIOLOGIA S/S LTDA | C10: laboratorio.pasteur@terra.com.br | E10: SÃO CARLOS | G10: =_xlfn.MINIFS(DADOS!$I:$I,DADOS!$B:$B,B10) -> 45366 | H10: =_xlfn.MAXIFS(DADOS!$I:$I,DADOS!$B:$B,B10) -> 46247 | I10: =CONFIG!$E$1-CLIENTES!H10 -> 7 | J10: =HYPERLINK("mailto:"&C10&"?subject="&CONFIG!$G$1&"&body="&CONFIG!$G$3,"Enviar e-mail") -> Enviar e-mail
A11: 463 | B11: MASUDA & MASUDA LABORATORIO CLINICO LTDA | C11: ltlabanalisesclinicas_pb@hotmail.com | E11: PEREIRA BARRETO | G11: =_xlfn.MINIFS(DADOS!$I:$I,DADOS!$B:$B,B11) -> 45359 | H11: =_xlfn.MAXIFS(DADOS!$I:$I,DADOS!$B:$B,B11) -> 46247 | I11: =CONFIG!$E$1-CLIENTES!H11 -> 7 | J11: =HYPERLINK("mailto:"&C11&"?subject="&CONFIG!$G$1&"&body="&CONFIG!$G$3,"Enviar e-mail") -> Enviar e-mail
A12: 474 | B12: LABORATI LAB. ANAL. CLIN. TIETE S/C LTDA. | C12: contato@laboratoriolaborati.com.br | E12: TIETE | G12: =_xlfn.MINIFS(DADOS!$I:$I,DADOS!$B:$B,B12) -> 45428 | H12: =_xlfn.MAXIFS(DADOS!$I:$I,DADOS!$B:$B,B12) -> 46233 | I12: =CONFIG!$E$1-CLIENTES!H12 -> 21 | J12: =HYPERLINK("mailto:"&C12&"?subject="&CONFIG!$G$1&"&body="&CONFIG!$G$3,"Enviar e-mail") -> Enviar e-mail
A13: 475 | B13: LABORATORIO DE ANALISES CLINICAS SRC LTDA | C13: faturamento.laboratoriosrc@gmail.com | E13: CATANDUVA | G13: =_xlfn.MINIFS(DADOS!$I:$I,DADOS!$B:$B,B13) -> 45357 | H13: =_xlfn.MAXIFS(DADOS!$I:$I,DADOS!$B:$B,B13) -> 46239 | I13: =CONFIG!$E$1-CLIENTES!H13 -> 15 | J13: =HYPERLINK("mailto:"&C13&"?subject="&CONFIG!$G$1&"&body="&CONFIG!$G$3,"Enviar e-mail") -> Enviar e-mail
... A39: 823 | B39: SANCHES x SANCHES S/C LTDA | C39: laboratoriodrlauro@gmail.com | E39: CATANDUVA | G39: =_xlfn.MINIFS(DADOS!$I:$I,DADOS!$B:$B,B39) -> 45356 | H39: =_xlfn.MAXIFS(DADOS!$I:$I,DADOS!$B:$B,B39) -> 46233 | I39: =CONFIG!$E$1-CLIENTES!H39 -> 21 | J39: =HYPERLINK("mailto:"&C39&"?subject="&CONFIG!$G$1&"&body="&CONFIG!$G$3,"Enviar e-mail") -> Enviar e-mail
A40: 832 | B40: ASSOCIACAO DE ENSINO E CULTURA DE MATO GROSSO | C40: almoxarifado@unilago.edu.br | E40: TRES LAGOAS | F40: FACULDADE | G40: =_xlfn.MINIFS(DADOS!$I:$I,DADOS!$B:$B,B40) -> 45359 | H40: =_xlfn.MAXIFS(DADOS!$I:$I,DADOS!$B:$B,B40) -> 46234 | I40: =CONFIG!$E$1-CLIENTES!H40 -> 20 | J40: =HYPERLINK("mailto:"&C40&"?subject="&CONFIG!$G$1&"&body="&CONFIG!$G$3,"Enviar e-mail") -> Enviar e-mail
A41: 874 | B41: LAB.ANAL.CLIN ABI JAUDI SC LTDA. | C41: pabijaudi@gmail.com | E41: AMERICO BRASILIENSE | G41: =_xlfn.MINIFS(DADOS!$I:$I,DADOS!$B:$B,B41) -> 45370 | H41: =_xlfn.MAXIFS(DADOS!$I:$I,DADOS!$B:$B,B41) -> 46218 | I41: =CONFIG!$E$1-CLIENTES!H41 -> 36 | J41: =HYPERLINK("mailto:"&C41&"?subject="&CONFIG!$G$1&"&body="&CONFIG!$G$3,"Enviar e-mail") -> Enviar e-mail
A42: 885 | B42: MEDCLINICA MORATENSE SC LTDA ME | C42: medclinicamoratense@hotmail.com | E42: FRANCISCO MORATO | F42: LABORATORIO | G42: =_xlfn.MINIFS(DADOS!$I:$I,DADOS!$B:$B,B42) -> 45414 | H42: =_xlfn.MAXIFS(DADOS!$I:$I,DADOS!$B:$B,B42) -> 45663 | I42: =CONFIG!$E$1-CLIENTES!H42 -> 591 | J42: =HYPERLINK("mailto:"&C42&"?subject="&CONFIG!$G$1&"&body="&CONFIG!$G$3,"Enviar e-mail") -> Enviar e-mail
A43: 905 | B43: LAB AN CLIN DR NESTOR FERRAREZZI FILHO SC LTDA | C43: labnestor@hotmail.com | E43: SEVERINIA | F43: LABORATORIO | G43: =_xlfn.MINIFS(DADOS!$I:$I,DADOS!$B:$B,B43) -> 45384 | H43: =_xlfn.MAXIFS(DADOS!$I:$I,DADOS!$B:$B,B43) -> 46230 | I43: =CONFIG!$E$1-CLIENTES!H43 -> 24 | J43: =HYPERLINK("mailto:"&C43&"?subject="&CONFIG!$G$1&"&body="&CONFIG!$G$3,"Enviar e-mail") -> Enviar e-mail
A44: 906 | B44: LABORATORIO ANAL. CLIN. DESCALVADO LTDA | C44: labdescalvado@gmail.com | E44: DESCALVADO | G44: =_xlfn.MINIFS(DADOS!$I:$I,DADOS!$B:$B,B44) -> 45358 | H44: =_xlfn.MAXIFS(DADOS!$I:$I,DADOS!$B:$B,B44) -> 46230 | I44: =CONFIG!$E$1-CLIENTES!H44 -> 24 | J44: =HYPERLINK("mailto:"&C44&"?subject="&CONFIG!$G$1&"&body="&CONFIG!$G$3,"Enviar e-mail") -> Enviar e-mail
A45: 960 | B45: LUIS VALERIO FILHO-ME | C45: patricia.azuaga@gmail.com | E45: MARAPOAMA | G45: =_xlfn.MINIFS(DADOS!$I:$I,DADOS!$B:$B,B45) -> 45359 | H45: =_xlfn.MAXIFS(DADOS!$I:$I,DADOS!$B:$B,B45) -> 46238 | I45: =CONFIG!$E$1-CLIENTES!H45 -> 16 | J45: =HYPERLINK("mailto:"&C45&"?subject="&CONFIG!$G$1&"&body="&CONFIG!$G$3,"Enviar e-mail") -> Enviar e-mail
A46: 980 | B46: LAB. GUARARAPES ANAL. CLIN. SC LTDA | C46: laboratorioguararapes@gmail.com | E46: GUARARAPES | F46: LABORATORIO | G46: =_xlfn.MINIFS(DADOS!$I:$I,DADOS!$B:$B,B46) -> 45397 | H46: =_xlfn.MAXIFS(DADOS!$I:$I,DADOS!$B:$B,B46) -> 46182 | I46: =CONFIG!$E$1-CLIENTES!H46 -> 72 | J46: =HYPERLINK("mailto:"&C46&"?subject="&CONFIG!$G$1&"&body="&CONFIG!$G$3,"Enviar e-mail") -> Enviar e-mail
A47: 1016 | B47: LAB.ANAL.CLIN. SAO LUCAS SC LTDA. | C47: labolucas@gmail.com | E47: MIRANDOPOLIS | G47: =_xlfn.MINIFS(DADOS!$I:$I,DADOS!$B:$B,B47) -> 45446 | H47: =_xlfn.MAXIFS(DADOS!$I:$I,DADOS!$B:$B,B47) -> 46220 | I47: =CONFIG!$E$1-CLIENTES!H47 -> 34 | J47: =HYPERLINK("mailto:"&C47&"?subject="&CONFIG!$G$1&"&body="&CONFIG!$G$3,"Enviar e-mail") -> Enviar e-mail
A48: 1026 | B48: LABSC SERVICOS LABORATORIAIS LTDA | C48: cfabriciof@hotmail.com | E48: SANTA ADELIA | G48: =_xlfn.MINIFS(DADOS!$I:$I,DADOS!$B:$B,B48) -> 45352 | H48: =_xlfn.MAXIFS(DADOS!$I:$I,DADOS!$B:$B,B48) -> 46183 | I48: =CONFIG!$E$1-CLIENTES!H48 -> 71 | J48: =HYPERLINK("mailto:"&C48&"?subject="&CONFIG!$G$1&"&body="&CONFIG!$G$3,"Enviar e-mail") -> Enviar e-mail
A49: 1041 | B49: EDSON VANDERLEI CARRERA | C49: edson.carrera@hotmail.com | E49: SANTA CRUZ DA CONCEICAO | G49: =_xlfn.MINIFS(DADOS!$I:$I,DADOS!$B:$B,B49) -> 45394 | H49: =_xlfn.MAXIFS(DADOS!$I:$I,DADOS!$B:$B,B49) -> 45841 | I49: =CONFIG!$E$1-CLIENTES!H49 -> 413 | J49: =HYPERLINK("mailto:"&C49&"?subject="&CONFIG!$G$1&"&body="&CONFIG!$G$3,"Enviar e-mail") -> Enviar e-mail
A50: 1058 | B50: LAB. ANAL. CLIN. DR ARNALDO BUAINAIN SS LTDA | C50: lab.buainain@uol.com.br | E50: ARARAQUARA | F50: LABORATORIO | G50: =_xlfn.MINIFS(DADOS!$I:$I,DADOS!$B:$B,B50) -> 45352 | H50: =_xlfn.MAXIFS(DADOS!$I:$I,DADOS!$B:$B,B50) -> 46128 | I50: =CONFIG!$E$1-CLIENTES!H50 -> 126 | J50: =HYPERLINK("mailto:"&C50&"?subject="&CONFIG!$G$1&"&body="&CONFIG!$G$3,"Enviar e-mail") -> Enviar e-mail
A51: 1122 | B51: FUNDEPAG | C51: ceav.biologico@gmail.com | E51: SAO PAULO | G51: =_xlfn.MINIFS(DADOS!$I:$I,DADOS!$B:$B,B51) -> 45411 | H51: =_xlfn.MAXIFS(DADOS!$I:$I,DADOS!$B:$B,B51) -> 46218 | I51: =CONFIG!$E$1-CLIENTES!H51 -> 36 | J51: =HYPERLINK("mailto:"&C51&"?subject="&CONFIG!$G$1&"&body="&CONFIG!$G$3,"Enviar e-mail") -> Enviar e-mail
A52: 1158 | B52: FUNDACAO DE DESENVOLVIMENTO DA PESQUISA | C52: samuelsilva@fundep.com.br | E52: BELO HORIZONTE | G52: =_xlfn.MINIFS(DADOS!$I:$I,DADOS!$B:$B,B52) -> 45586 | H52: =_xlfn.MAXIFS(DADOS!$I:$I,DADOS!$B:$B,B52) -> 45586 | I52: =CONFIG!$E$1-CLIENTES!H52 -> 668 | J52: =HYPERLINK("mailto:"&C52&"?subject="&CONFIG!$G$1&"&body="&CONFIG!$G$3,"Enviar e-mail") -> Enviar e-mail
A53: 1164 | B53: LAB. ANAL. CLIN. SAO LOURENCO S/C LTDA | C53: luizantonio_ciocca@hotmail.com | E53: URUPES | G53: =_xlfn.MINIFS(DADOS!$I:$I,DADOS!$B:$B,B53) -> 45372 | H53: =_xlfn.MAXIFS(DADOS!$I:$I,DADOS!$B:$B,B53) -> 46232 | I53: =CONFIG!$E$1-CLIENTES!H53 -> 22 | J53: =HYPERLINK("mailto:"&C53&"?subject="&CONFIG!$G$1&"&body="&CONFIG!$G$3,"Enviar e-mail") -> Enviar e-mail
A54: 1206 | B54: LABORATORIO RIO NEGRO CENTER DE MARILIA LTDA | C54: biolabormarilia@hotmail.com | E54: MARILIA | G54: =_xlfn.MINIFS(DADOS!$I:$I,DADOS!$B:$B,B54) -> 45362 | H54: =_xlfn.MAXIFS(DADOS!$I:$I,DADOS!$B:$B,B54) -> 46234 | I54: =CONFIG!$E$1-CLIENTES!H54 -> 20 | J54: =HYPERLINK("mailto:"&C54&"?subject="&CONFIG!$G$1&"&body="&CONFIG!$G$3,"Enviar e-mail") -> Enviar e-mail
A55: 1240 | B55: MONICA VIEIRA DE CAMPOS REBELO-ME | C55: laboratoriosaobento@hotmail.com | E55: CONCHAS | G55: =_xlfn.MINIFS(DADOS!$I:$I,DADOS!$B:$B,B55) -> 45357 | H55: =_xlfn.MAXIFS(DADOS!$I:$I,DADOS!$B:$B,B55) -> 46218 | I55: =CONFIG!$E$1-CLIENTES!H55 -> 36 | J55: =HYPERLINK("mailto:"&C55&"?subject="&CONFIG!$G$1&"&body="&CONFIG!$G$3,"Enviar e-mail") -> Enviar e-mail
A56: 1318 | B56: LABORATORIO DE ANALISES CLINICAS VITAL BRAZIL LTDA EPP | C56: compras@lvb.com.br | E56: CAMPINAS | G56: =_xlfn.MINIFS(DADOS!$I:$I,DADOS!$B:$B,B56) -> 45567 | H56: =_xlfn.MAXIFS(DADOS!$I:$I,DADOS!$B:$B,B56) -> 45567 | I56: =CONFIG!$E$1-CLIENTES!H56 -> 687 | J56: =HYPERLINK("mailto:"&C56&"?subject="&CONFIG!$G$1&"&body="&CONFIG!$G$3,"Enviar e-mail") -> Enviar e-mail
A57: 1371 | B57: MICHELE LOPES BERGAMIM-ME | C57: biomedimiberga@hotmail.com | E57: IBIRA | G57: =_xlfn.MINIFS(DADOS!$I:$I,DADOS!$B:$B,B57) -> 45588 | H57: =_xlfn.MAXIFS(DADOS!$I:$I,DADOS!$B:$B,B57) -> 46211 | I57: =CONFIG!$E$1-CLIENTES!H57 -> 43 | J57: =HYPERLINK("mailto:"&C57&"?subject="&CONFIG!$G$1&"&body="&CONFIG!$G$3,"Enviar e-mail") -> Enviar e-mail
A58: 1493 | B58: CEDIMA CENTRO DE DIAG MONTE AZUL ANAL CLIN E CIT | C58: laboratorio.cedima@bol.com.br | E58: MONTE AZUL PAULISTA | G58: =_xlfn.MINIFS(DADOS!$I:$I,DADOS!$B:$B,B58) -> 45357 | H58: =_xlfn.MAXIFS(DADOS!$I:$I,DADOS!$B:$B,B58) -> 46218 | I58: =CONFIG!$E$1-CLIENTES!H58 -> 36 | J58: =HYPERLINK("mailto:"&C58&"?subject="&CONFIG!$G$1&"&body="&CONFIG!$G$3,"Enviar e-mail") -> Enviar e-mail
A59: 1502 | B59: ASSOC.CASA DE SAUDE BEN. DE INDIAPORA | C59: laboratorioacsbi@gmail.com.br | E59: INDIAPORA | G59: =_xlfn.MINIFS(DADOS!$I:$I,DADOS!$B:$B,B59) -> 45387 | H59: =_xlfn.MAXIFS(DADOS!$I:$I,DADOS!$B:$B,B59) -> 45953 | I59: =CONFIG!$E$1-CLIENTES!H59 -> 301 | J59: =HYPERLINK("mailto:"&C59&"?subject="&CONFIG!$G$1&"&body="&CONFIG!$G$3,"Enviar e-mail") -> Enviar e-mail
A60: 1533 | B60: LABORATORIO BIOANALISE DIAGNOSTICO LTDA | C60: qualidadebioanalise@gmail.com | E60: MATAO | G60: =_xlfn.MINIFS(DADOS!$I:$I,DADOS!$B:$B,B60) -> 45369 | H60: =_xlfn.MAXIFS(DADOS!$I:$I,DADOS!$B:$B,B60) -> 46246 | I60: =CONFIG!$E$1-CLIENTES!H60 -> 8 | J60: =HYPERLINK("mailto:"&C60&"?subject="&CONFIG!$G$1&"&body="&CONFIG!$G$3,"Enviar e-mail") -> Enviar e-mail
A61: 1534 | B61: CISCRE IMPORTACAO E DISTRIBUICAO DE PRODUTOS MEDICOS LTDA | C61: fabiana@ciscre.com.br | E61: CAMPINAS | F61: LABORATORIO | G61: =_xlfn.MINIFS(DADOS!$I:$I,DADOS!$B:$B,B61) -> 45474 | H61: =_xlfn.MAXIFS(DADOS!$I:$I,DADOS!$B:$B,B61) -> 46203 | I61: =CONFIG!$E$1-CLIENTES!H61 -> 51 | J61: =HYPERLINK("mailto:"&C61&"?subject="&CONFIG!$G$1&"&body="&CONFIG!$G$3,"Enviar e-mail") -> Enviar e-mail
A62: 1616 | B62: NOVO HORIZONTE LAB.ANAL.CLIN.S/C LTDA. | C62: everaldojoselazari@gmail.com | E62: NOVO HORIZONTE | G62: =_xlfn.MINIFS(DADOS!$I:$I,DADOS!$B:$B,B62) -> 45406 | H62: =_xlfn.MAXIFS(DADOS!$I:$I,DADOS!$B:$B,B62) -> 46239 | I62: =CONFIG!$E$1-CLIENTES!H62 -> 15 | J62: =HYPERLINK("mailto:"&C62&"?subject="&CONFIG!$G$1&"&body="&CONFIG!$G$3,"Enviar e-mail") -> Enviar e-mail
A63: 1623 | B63: LAB.ANAL.CLIN. E REP. BADY BASSIT LTDA | C63: labbady@terra.com.br | E63: BADY BASSITT | G63: =_xlfn.MINIFS(DADOS!$I:$I,DADOS!$B:$B,B63) -> 45371 | H63: =_xlfn.MAXIFS(DADOS!$I:$I,DADOS!$B:$B,B63) -> 46136 | I63: =CONFIG!$E$1-CLIENTES!H63 -> 118 | J63: =HYPERLINK("mailto:"&C63&"?subject="&CONFIG!$G$1&"&body="&CONFIG!$G$3,"Enviar e-mail") -> Enviar e-mail
A64: 1652 | B64: LAB. SANTA CLARA ANAL.CLIN. | C64: lab.santaclara@terra.com.br | E64: FERNANDOPOLIS | G64: =_xlfn.MINIFS(DADOS!$I:$I,DADOS!$B:$B,B64) -> 45376 | H64: =_xlfn.MAXIFS(DADOS!$I:$I,DADOS!$B:$B,B64) -> 46226 | I64: =CONFIG!$E$1-CLIENTES!H64 -> 28 | J64: =HYPERLINK("mailto:"&C64&"?subject="&CONFIG!$G$1&"&body="&CONFIG!$G$3,"Enviar e-mail") -> Enviar e-mail
A65: 1726 | B65: IRMANDADE DA SANTA CASA DE MISERIC. DE MOGI MIRIM | C65: francisco.rangel@santacasamogi.com.br | E65: MOGI-MIRIM | G65: =_xlfn.MINIFS(DADOS!$I:$I,DADOS!$B:$B,B65) -> 45362 | H65: =_xlfn.MAXIFS(DADOS!$I:$I,DADOS!$B:$B,B65) -> 46108 | I65: =CONFIG!$E$1-CLIENTES!H65 -> 146 | J65: =HYPERLINK("mailto:"&C65&"?subject="&CONFIG!$G$1&"&body="&CONFIG!$G$3,"Enviar e-mail") -> Enviar e-mail
...

Sheet DADOS
A1: CLIENTE | B1: NOME | C1: ENVIO | D1: PEDIDO INSUMOS | E1: VALOR INSUMOS | F1: PEDIDO EQUIPAMENTO | G1: VALOR EQUIPAMENTO | H1: LOCAÇÃO | I1: DATA
A2: 705 | B2: =IFERROR(VLOOKUP(A2,CLIENTES!A:E,2,0),"CADASTRAR CLIENTE") -> JOAO JOSE SCHIAVUZZO ME | C2: WHATS | D2: 70919 | E2: 389.35 | I2: 45352
A3: 705 | B3: =IFERROR(VLOOKUP(A3,CLIENTES!A:E,2,0),"CADASTRAR CLIENTE") -> JOAO JOSE SCHIAVUZZO ME | C3: WHATS | D3: 98127 | E3: 884.95 | I3: 45352
A4: 50558 | B4: =IFERROR(VLOOKUP(A4,CLIENTES!A:E,2,0),"CADASTRAR CLIENTE") -> FUNDACAO PAULISTA DE TECNOLOGIA E EDUCACAO | C4: EMAIL | D4: 71252 | E4: 3005.2 | I4: 45352
A5: 50558 | B5: =IFERROR(VLOOKUP(A5,CLIENTES!A:E,2,0),"CADASTRAR CLIENTE") -> FUNDACAO PAULISTA DE TECNOLOGIA E EDUCACAO | C5: EMAIL | D5: 72125 | E5: 2585 | I5: 45352
A6: 746 | B6: =IFERROR(VLOOKUP(A6,CLIENTES!A:E,2,0),"CADASTRAR CLIENTE") -> LAB.ANAL.CLIN.BIOCLIN SC LTDA. | C6: TEL | D6: 71236 | E6: 2994.26 | I6: 45352
A7: 746 | B7: =IFERROR(VLOOKUP(A7,CLIENTES!A:E,2,0),"CADASTRAR CLIENTE") -> LAB.ANAL.CLIN.BIOCLIN SC LTDA. | C7: TEL | D7: 98201 | E7: 273.3 | I7: 45352
A8: 731 | B8: =IFERROR(VLOOKUP(A8,CLIENTES!A:E,2,0),"CADASTRAR CLIENTE") -> UNILAB LABORATORIO ANALISES CLINICAS SANTA FE DO SUL LTDA | C8: WHATS | D8: 71126 | E8: 744 | I8: 45352
A9: 50600 | B9: =IFERROR(VLOOKUP(A9,CLIENTES!A:E,2,0),"CADASTRAR CLIENTE") -> CADASTRAR CLIENTE | C9: WHATS | D9: 70713 | E9: 846.59 | I9: 45352
A10: 50600 | B10: =IFERROR(VLOOKUP(A10,CLIENTES!A:E,2,0),"CADASTRAR CLIENTE") -> CADASTRAR CLIENTE | C10: WHATS | D10: 71101 | E10: 1640 | I10: 45352
A11: 1058 | B11: =IFERROR(VLOOKUP(A11,CLIENTES!A:E,2,0),"CADASTRAR CLIENTE") -> LAB. ANAL. CLIN. DR ARNALDO BUAINAIN SS LTDA | C11: WHATS | D11: 71247 | E11: 600 | I11: 45352
A12: 2397 | B12: =IFERROR(VLOOKUP(A12,CLIENTES!A:E,2,0),"CADASTRAR CLIENTE") -> LAB ANAL CLINICAS SANTA RITA S/C LTDA | C12: TEL | D12: 70924 | E12: 969 | I12: 45352
A13: 1026 | B13: =IFERROR(VLOOKUP(A13,CLIENTES!A:E,2,0),"CADASTRAR CLIENTE") -> LABSC SERVICOS LABORATORIAIS LTDA | C13: EMAIL | D13: 71230 | E13: 532 | I13: 45352
... A76: 756 | B76: =IFERROR(VLOOKUP(A76,CLIENTES!A:E,2,0),"CADASTRAR CLIENTE") -> LAB.TRIANON DE ANAL.CLIN.SC LTDA. | C76: WHATS | D76: 71636 | E76: 1125.91 | I76: 45364
A77: 906 | B77: =IFERROR(VLOOKUP(A77,CLIENTES!A:E,2,0),"CADASTRAR CLIENTE") -> LABORATORIO ANAL. CLIN. DESCALVADO LTDA | C77: WHATS | D77: 71646 | E77: 8134 | F77: 1 | G77: 6980 | I77: 45364
A78: 762 | B78: =IFERROR(VLOOKUP(A78,CLIENTES!A:E,2,0),"CADASTRAR CLIENTE") -> STA. CASA MISERICORDIA DE ARACATUBA | C78: WHATS | D78: 71410 | E78: 5556.94 | I78: 45364
A79: 762 | B79: =IFERROR(VLOOKUP(A79,CLIENTES!A:E,2,0),"CADASTRAR CLIENTE") -> STA. CASA MISERICORDIA DE ARACATUBA | C79: WHATS | D79: 71410 | E79: 10289.85 | I79: 45364
A80: 724 | B80: =IFERROR(VLOOKUP(A80,CLIENTES!A:E,2,0),"CADASTRAR CLIENTE") -> LAB. ANAL. CLIN. DRA SILVIA M.MANZATO LARANJO SC LTDA. | C80: WHATS | D80: 71670 | E80: 978.8 | I80: 45364
A81: 475 | B81: =IFERROR(VLOOKUP(A81,CLIENTES!A:E,2,0),"CADASTRAR CLIENTE") -> LABORATORIO DE ANALISES CLINICAS SRC LTDA | C81: WHATS | D81: 71693 | E81: 3860 | I81: 45365
A82: 1194 | B82: =IFERROR(VLOOKUP(A82,CLIENTES!A:E,2,0),"CADASTRAR CLIENTE") -> CADASTRAR CLIENTE | C82: TEL | D82: 71484 | E82: 572 | I82: 45365
A83: 335 | B83: =IFERROR(VLOOKUP(A83,CLIENTES!A:E,2,0),"CADASTRAR CLIENTE") -> LABORATORIO VIDA S/S LTDA | C83: TEL | D83: 98205 | E83: 43.6 | I83: 45365
A84: 335 | B84: =IFERROR(VLOOKUP(A84,CLIENTES!A:E,2,0),"CADASTRAR CLIENTE") -> LABORATORIO VIDA S/S LTDA | C84: TEL | D84: 71659 | E84: 47.5 | I84: 45365
A85: 432 | B85: =IFERROR(VLOOKUP(A85,CLIENTES!A:E,2,0),"CADASTRAR CLIENTE") -> LABORATORIO PASTEUR HEMATOLOGIA E MICROBIOLOGIA S/S LTDA | C85: WHATS | D85: 71686 | E85: 161.4 | I85: 45366
A86: 2203 | B86: =IFERROR(VLOOKUP(A86,CLIENTES!A:E,2,0),"CADASTRAR CLIENTE") -> FUNDACAO EDUCACIONAL DE ANDRADINA-FEA | C86: EMAIL | D86: 71649 | E86: 1473.2 | I86: 45366
A87: 50219 | B87: =IFERROR(VLOOKUP(A87,CLIENTES!A:E,2,0),"CADASTRAR CLIENTE") -> UNIPREV LAB DE ANALISES LOCACAO DE BENS E REPAROS LTDA EPP | C87: WHATS | D87: 71770 | E87: 60 | I87: 45369
A88: 746 | B88: =IFERROR(VLOOKUP(A88,CLIENTES!A:E,2,0),"CADASTRAR CLIENTE") -> LAB.ANAL.CLIN.BIOCLIN SC LTDA. | C88: TEL | D88: 71787 | E88: 1110 | I88: 45369
A89: 2022 | B89: =IFERROR(VLOOKUP(A89,CLIENTES!A:E,2,0),"CADASTRAR CLIENTE") -> LAB. MEDICO DR. MARICONDI S/C LTDA. | C89: WHATS | D89: 71465 | E89: 308 | I89: 45369
... A249: 1533 | B249: =IFERROR(VLOOKUP(A249,CLIENTES!A:E,2,0),"CADASTRAR CLIENTE") -> LABORATORIO BIOANALISE DIAGNOSTICO LTDA | C249: WHATS | D249: 72651 | E249: 706.2 | I249: 45394
A250: 513 | B250: =IFERROR(VLOOKUP(A250,CLIENTES!A:E,2,0),"CADASTRAR CLIENTE") -> CADASTRAR CLIENTE | C250: WHATS | D250: 72802 | E250: 2955 | F250: 1 | G250: 2995 | I250: 45394
A251: 1041 | B251: =IFERROR(VLOOKUP(A251,CLIENTES!A:E,2,0),"CADASTRAR CLIENTE") -> EDSON VANDERLEI CARRERA | C251: WHATS | D251: 72800 | E251: 594.5 | I251: 45394
A252: 762 | B252: =IFERROR(VLOOKUP(A252,CLIENTES!A:E,2,0),"CADASTRAR CLIENTE") -> STA. CASA MISERICORDIA DE ARACATUBA | C252: EMAIL | D252: 72610 | E252: 3974.3 | I252: 45394
A253: 762 | B253: =IFERROR(VLOOKUP(A253,CLIENTES!A:E,2,0),"CADASTRAR CLIENTE") -> STA. CASA MISERICORDIA DE ARACATUBA | C253: EMAIL | D253: 72611 | E253: 9420.38 | I253: 45394
A254: 51175 | B254: =IFERROR(VLOOKUP(A254,CLIENTES!A:E,2,0),"CADASTRAR CLIENTE") -> CLINICA MEDICA E ODONTOLOGICA AMOR SAUDE TUPA LTDA | C254: WHATS | D254: 72834 | E254: 164.15 | I254: 45397
A255: 3017 | B255: =IFERROR(VLOOKUP(A255,CLIENTES!A:E,2,0),"CADASTRAR CLIENTE") -> IMUNOLAB LABORATORIO DE ANALISES CLINICAS LTDA ME | C255: WHATS | D255: 72898 | E255: 657.88 | I255: 45397
A256: 980 | B256: =IFERROR(VLOOKUP(A256,CLIENTES!A:E,2,0),"CADASTRAR CLIENTE") -> LAB. GUARARAPES ANAL. CLIN. SC LTDA | C256: WHATS | D256: 72901 | E256: 142 | I256: 45397
A257: 620 | B257: =IFERROR(VLOOKUP(A257,CLIENTES!A:E,2,0),"CADASTRAR CLIENTE") -> LAB.SAO PAULO DE ANAL.CLIN.SC LTDA. | C257: WHATS | D257: 72909 | E257: 554.68 | I257: 45397
A258: 1806 | B258: =IFERROR(VLOOKUP(A258,CLIENTES!A:E,2,0),"CADASTRAR CLIENTE") -> LABORATORIO DE ANALISES CLINICAS SENTOME LTDA-ME | C258: EMAIL | D258: 72888 | E258: 822.6 | I258: 45397
A259: 335 | B259: =IFERROR(VLOOKUP(A259,CLIENTES!A:E,2,0),"CADASTRAR CLIENTE") -> LABORATORIO VIDA S/S LTDA | C259: WHATS | D259: 72874 | E259: 379.47 | I259: 45397
A260: 335 | B260: =IFERROR(VLOOKUP(A260,CLIENTES!A:E,2,0),"CADASTRAR CLIENTE") -> LABORATORIO VIDA S/S LTDA | C260: WHATS | D260: 98497 | E260: 432.3 | I260: 45397
A261: 620 | B261: =IFERROR(VLOOKUP(A261,CLIENTES!A:E,2,0),"CADASTRAR CLIENTE") -> LAB.SAO PAULO DE ANAL.CLIN.SC LTDA. | C261: WHATS | D261: 98509 | E261: 220.2 | I261: 45397
...

Sheet DASHBOARD 3.0
B2: =B7+B10 -> 143312.18 | E2: =B2/CONFIG!B3 -> 0.49761174 | H2: TOP 20 CLIENTES
H3: SKU | I3: NOME | J3: VALORES INSUMOS | K3: VALORES EQUIPAMENTOS | L3: % VENDA | M3: CIDADE
B4: VENDAS TOTAIS | E4: META MENSAL | H4: =INDEX(CLIENTES!A:A,(MATCH('DASHBOARD 3.0'!I4,CLIENTES!B:B,0))) -> 475 | I4: LABORATORIO DE ANALISES CLINICAS SRC LTDA | J4: 15586.8 | L4: =(J4+K4)/$B$2 -> 0.10876117 | M4: =INDEX(CLIENTES!E:E,(MATCH('DASHBOARD 3.0'!I4,CLIENTES!B:B,0))) -> CATANDUVA
H5: =INDEX(CLIENTES!A:A,(MATCH('DASHBOARD 3.0'!I5,CLIENTES!B:B,0))) -> 761 | I5: EXAME CENTRO DIAG.M.ARACATUBA SC LTDA. | J5: 13246.72 | L5: =(J5+K5)/$B$2 -> 0.092432618 | M5: =INDEX(CLIENTES!E:E,(MATCH('DASHBOARD 3.0'!I5,CLIENTES!B:B,0))) -> ARACATUBA
H6: =INDEX(CLIENTES!A:A,(MATCH('DASHBOARD 3.0'!I6,CLIENTES!B:B,0))) -> 501033 | I6: EASYMED SERVICOS MEDICOS LTDA | J6: 12947.81 | L6: =(J6+K6)/$B$2 -> 0.090346892 | M6: =INDEX(CLIENTES!E:E,(MATCH('DASHBOARD 3.0'!I6,CLIENTES!B:B,0))) -> 0
B7: =DINAMICOS!$B$1 -> 135392.18 | E7: =B2/(CONFIG!B3*12) -> 0.041467645 | H7: =INDEX(CLIENTES!A:A,(MATCH('DASHBOARD 3.0'!I7,CLIENTES!B:B,0))) -> 762 | I7: STA. CASA MISERICORDIA DE ARACATUBA | J7: 7411.61 | L7: =(J7+K7)/$B$2 -> 0.051716539 | M7: =INDEX(CLIENTES!E:E,(MATCH('DASHBOARD 3.0'!I7,CLIENTES!B:B,0))) -> ARACATUBA
B8: VENDAS ISUMOS | H8: =INDEX(CLIENTES!A:A,(MATCH('DASHBOARD 3.0'!I8,CLIENTES!B:B,0))) -> 3557 | I8: ASSOCIACAO BENEFICIENTE NOSSA SENHORA DE NAZARE | J8: 5730.55 | L8: =(J8+K8)/$B$2 -> 0.039986483 | M8: =INDEX(CLIENTES!E:E,(MATCH('DASHBOARD 3.0'!I8,CLIENTES!B:B,0))) -> SÃO PAULO
E9: META ANUAL | H9: =INDEX(CLIENTES!A:A,(MATCH('DASHBOARD 3.0'!I9,CLIENTES!B:B,0))) -> 501153 | I9: LABORATORIO SAO ROQUE LTDA | J9: 5420.39 | L9: =(J9+K9)/$B$2 -> 0.037822256 | M9: =INDEX(CLIENTES!E:E,(MATCH('DASHBOARD 3.0'!I9,CLIENTES!B:B,0))) -> 0
B10: =DINAMICOS!$D$1 -> 7920 | H10: =INDEX(CLIENTES!A:A,(MATCH('DASHBOARD 3.0'!I10,CLIENTES!B:B,0))) -> 690 | I10: SAO ROQUE MEDICINA DIAGNOSTICA LTDA EPP | J10: 4273.04 | L10: =(J10+K10)/$B$2 -> 0.029816307 | M10: =INDEX(CLIENTES!E:E,(MATCH('DASHBOARD 3.0'!I10,CLIENTES!B:B,0))) -> JALES
B11: VENDAS EQUIPAMENTOS | H11: =INDEX(CLIENTES!A:A,(MATCH('DASHBOARD 3.0'!I11,CLIENTES!B:B,0))) -> 500005 | I11: ASSOCIACAO EDUCACIONAL DE ENSINO SUPERIOR | J11: 3947.1 | K11: 6580 | L11: =(J11+K11)/$B$2 -> 0.073455724 | M11: =INDEX(CLIENTES!E:E,(MATCH('DASHBOARD 3.0'!I11,CLIENTES!B:B,0))) -> SAO JOSE DO RIO PRETO
H12: =INDEX(CLIENTES!A:A,(MATCH('DASHBOARD 3.0'!I12,CLIENTES!B:B,0))) -> 2955 | I12: ASSOCIACAO SANTA CASA SAUDE DE ARACATUBA | J12: 3931.1 | L12: =(J12+K12)/$B$2 -> 0.027430327 | M12: =INDEX(CLIENTES!E:E,(MATCH('DASHBOARD 3.0'!I12,CLIENTES!B:B,0))) -> ARACATUBA
B13: =DINAMICOS!$F$1 -> 47 | H13: =INDEX(CLIENTES!A:A,(MATCH('DASHBOARD 3.0'!I13,CLIENTES!B:B,0))) -> 325 | I13: EXAME-LABORAT. DE ANAL. CLIN. CITODIAGNOSTICO S/S LTDA | J13: 3695.45 | L13: =(J13+K13)/$B$2 -> 0.025786015 | M13: =INDEX(CLIENTES!E:E,(MATCH('DASHBOARD 3.0'!I13,CLIENTES!B:B,0))) -> PRESIDENTE PRUDENTE
B14: PEDIDOS INSUMOS | H14: =INDEX(CLIENTES!A:A,(MATCH('DASHBOARD 3.0'!I14,CLIENTES!B:B,0))) -> 516 | I14: TECNOLAB PATOLOGIA CLINICA S/C LTDA | J14: 3597.6 | L14: =(J14+K14)/$B$2 -> 0.02510324 | M14: =INDEX(CLIENTES!E:E,(MATCH('DASHBOARD 3.0'!I14,CLIENTES!B:B,0))) -> BAURU
H15: =INDEX(CLIENTES!A:A,(MATCH('DASHBOARD 3.0'!I15,CLIENTES!B:B,0))) -> 500507 | I15: LABORATORIOS DOCTOR | J15: 3521.52 | L15: =(J15+K15)/$B$2 -> 0.024572371 | M15: =INDEX(CLIENTES!E:E,(MATCH('DASHBOARD 3.0'!I15,CLIENTES!B:B,0))) -> ITU
B16: =DINAMICOS!$H$1 -> 0 | H16: =INDEX(CLIENTES!A:A,(MATCH('DASHBOARD 3.0'!I16,CLIENTES!B:B,0))) -> 500149 | I16: SAO ROQUE MEDICINA DIAGNOSTICA LTDA | J16: 3429.9 | L16: =(J16+K16)/$B$2 -> 0.023933067 | M16: =INDEX(CLIENTES!E:E,(MATCH('DASHBOARD 3.0'!I16,CLIENTES!B:B,0))) -> SINOP
B17: PEDIDOS EQUIPAMENTOS | H17: =INDEX(CLIENTES!A:A,(MATCH('DASHBOARD 3.0'!I17,CLIENTES!B:B,0))) -> 2572 | I17: LAB. ANAL. CLIN. COFFERS S/C LTDA | J17: 3380.62 | L17: =(J17+K17)/$B$2 -> 0.023589202 | M17: =INDEX(CLIENTES!E:E,(MATCH('DASHBOARD 3.0'!I17,CLIENTES!B:B,0))) -> SANTA CRUZ DO RIO PARDO
H18: =INDEX(CLIENTES!A:A,(MATCH('DASHBOARD 3.0'!I18,CLIENTES!B:B,0))) -> 480 | I18: LAB SAO LUCAS | J18: 3258.5 | L18: =(J18+K18)/$B$2 -> 0.022737076 | M18: =INDEX(CLIENTES!E:E,(MATCH('DASHBOARD 3.0'!I18,CLIENTES!B:B,0))) -> TABATINGA
H19: =INDEX(CLIENTES!A:A,(MATCH('DASHBOARD 3.0'!I19,CLIENTES!B:B,0))) -> 581 | I19: CLINILAB LABORAT. ANAL. CLIN SC LTDA | J19: 3197.08 | L19: =(J19+K19)/$B$2 -> 0.022308502 | M19: =INDEX(CLIENTES!E:E,(MATCH('DASHBOARD 3.0'!I19,CLIENTES!B:B,0))) -> IBITINGA
H20: =INDEX(CLIENTES!A:A,(MATCH('DASHBOARD 3.0'!I20,CLIENTES!B:B,0))) -> 434 | I20: BIOLABOR LAB. ANAL. CLIN. SC LTDA. | J20: 3101.2 | L20: =(J20+K20)/$B$2 -> 0.021639473 | M20: =INDEX(CLIENTES!E:E,(MATCH('DASHBOARD 3.0'!I20,CLIENTES!B:B,0))) -> 0
H21: =INDEX(CLIENTES!A:A,(MATCH('DASHBOARD 3.0'!I21,CLIENTES!B:B,0))) -> 311 | I21: CENTRO DE ANAL.CLIN. UNILAB SC LTDA. | J21: 2820.45 | K21: 1340 | L21: =(J21+K21)/$B$2 -> 0.02903068 | M21: =INDEX(CLIENTES!E:E,(MATCH('DASHBOARD 3.0'!I21,CLIENTES!B:B,0))) -> PRESIDENTE PRUDENTE
H22: =INDEX(CLIENTES!A:A,(MATCH('DASHBOARD 3.0'!I22,CLIENTES!B:B,0))) -> 3492 | I22: SOCIEDADE EDUCACIONAL UBERABENSE | J22: 2676.4 | L22: =(J22+K22)/$B$2 -> 0.018675314 | M22: =INDEX(CLIENTES!E:E,(MATCH('DASHBOARD 3.0'!I22,CLIENTES!B:B,0))) -> UBERABA
H23: =INDEX(CLIENTES!A:A,(MATCH('DASHBOARD 3.0'!I23,CLIENTES!B:B,0))) -> 50465 | I23: LABORATORIO DE ANALISES CLINICAS VIDA BIRIGUI LTDA | J23: 2415.98 | L23: =(J23+K23)/$B$2 -> 0.016858162 | M23: =INDEX(CLIENTES!E:E,(MATCH('DASHBOARD 3.0'!I23,CLIENTES!B:B,0))) -> BIRIGUI
I24: Total Geral | J24: 107589.82 | K24: 7920 | L24: =SUM(L4:L23) -> 0.80600142
